Workbook

Sheet Executive Report
A1: HHU LEDERRAPPORT 2026
A2: September YTD + Q4-prognose | 3–30–300 beslutningsvisning
A4: HELÅRSPROGNOSE | D4: SLUTTAVVIK (VAC) | G4: ÅRSVERK | J4: EVM EFFEKTIVITET | M4: STUDENTER
A5: =SUM(FactGL[Belop_signert]) -> 129631567 | D5: =SUM(FactBudget[BudsjettBelop])-SUM(FactGL[Belop_signert]) -> 522258 | G5: =SUMIFS(FactFTE[Aarsverk_Totalt],FactFTE[DatoNokkel],202612) -> 229 | J5: =MAX(FactEVM[CostPerformanceIndex_CPI]) -> 0.97 | M5: =SUMIFS(FactStudents_2027[RegistrerteStudenter],FactStudents_2027[DatoNokkel],20271031) -> 3450
A7: ="Budsjett "&TEXT(SUM(FactBudget[BudsjettBelop])/1000000,"0.0")&" MNOK" -> Budsjett 130.2 MNOK | D7: =IF(D5>=0,"🟢 Innenfor budsjett",IF(D5/SUM(FactBudget[BudsjettBelop])>=-5%,"🟡 Moderat avvik","🔴 Kritisk avvik")) -> 🟢 Innenfor budsjett | G7: =TEXT(SUMIFS(FactFTE[Aarsverk_UF],FactFTE[DatoNokkel],202612),"0")&" UF / "&TEXT(SUMIFS(FactFTE[Aarsverk_TA],FactFTE[DatoNokkel],202612),"0")&" TA" -> 154 UF / 75 TA | J7: ="🟡 CPI "&TEXT(J5,"0.00")&" | SPI "&TEXT(MAX(FactEVM[SchedulePerformanceIndex_SPI]),"0.00") -> 🟡 CPI 0.97 | SPI 0.98 | M7: =TEXT(SUMIFS(FactStudents_2027[SPE60],FactStudents_2027[DatoNokkel],20271031),"#,##0")&" SPE60 | "&TEXT(M5/SUMIFS(FactFTE_2027[Aarsverk_UF],FactFTE_2027[DatoNokkel],20271231),"0.0")&" stud./UF" -> 3,153 SPE60 | 22.3 stud./UF
A9: Visual RAG: grønn = innenfor plan | gul = 0–5 % over plan | rød = >5 % over plan
A10: Månedsutvikling: regnskap/prognose mot budsjett | J10: Sluttavvik per enhet
A27: LEDELSESKONKLUSJON
A28: 2026 ventes 0,52 MNOK innenfor budsjett, drevet av 1,15 MNOK mindreforbruk i Rettsvitenskap. Økonomi ligger 0,71 MNOK over plan, og EVM-indeksene CPI 0,97 / SPI 0,98 viser fortsatt moderat gjennomføringsrisiko. Prioriter BOA-frikjøp, EVU-kontroll og bemanningsstyring før årsavslutningen.
A32: Datagrunnlag: alle 432 budsjettlinjer, 433 GL-linjer, 48 FTE-rader og 12 studentrader.
A34: RAG: 🟢 innenfor mål | 🟡 moderat avvik / oppfølging | 🔴 kritisk avvik

Sheet Unit Analysis
A1: ENHETS- OG TILTAKSANALYSE 2026
A2: Avvik, bemanning og gjennomføring — full dekning av HHUs fire budsjettansvarsområder
A4: OrgKode | B4: Enhet | C4: Budsjett | D4: LE / helår | E4: Sluttavvik | F4: Avvik % | G4: UF-ÅV | H4: TA-ÅV | I4: Totale ÅV | J4: RAG
A5: K10000 | B5: Fakultetsadministrasjon & Felles | C5: =SUMIFS(FactBudget[BudsjettBelop],FactBudget[OrgKode],A5) -> 14000000 | D5: =SUMIFS(FactGL[Belop_signert],FactGL[OrgKode],A5) -> 13912501 | E5: =C5-D5 -> 87499 | F5: =E5/C5 -> 0.0062499286 | G5: =SUMIFS(FactFTE[Aarsverk_UF],FactFTE[OrgKode],A5,FactFTE[DatoNokkel],202612) -> 0 | H5: =SUMIFS(FactFTE[Aarsverk_TA],FactFTE[OrgKode],A5,FactFTE[DatoNokkel],202612) -> 22 | I5: =G5+H5 -> 22 | J5: =IF(F5>=0,"🟢 Innenfor",IF(F5>=-5%,"🟡 Følg opp","🔴 Kritisk")) -> 🟢 Innenfor
A6: K11000 | B6: Ledelse og innovasjon | C6: =SUMIFS(FactBudget[BudsjettBelop],FactBudget[OrgKode],A6) -> 38500000 | D6: =SUMIFS(FactGL[Belop_signert],FactGL[OrgKode],A6) -> 38503496 | E6: =C6-D6 -> -3496 | F6: =E6/C6 -> -9.0805195e-05 | G6: =SUMIFS(FactFTE[Aarsverk_UF],FactFTE[OrgKode],A6,FactFTE[DatoNokkel],202612) -> 45 | H6: =SUMIFS(FactFTE[Aarsverk_TA],FactFTE[OrgKode],A6,FactFTE[DatoNokkel],202612) -> 18 | I6: =G6+H6 -> 63 | J6: =IF(F6>=0,"🟢 Innenfor",IF(F6>=-5%,"🟡 Følg opp","🔴 Kritisk")) -> 🟡 Følg opp
A7: K12000 | B7: Rettsvitenskap | C7: =SUMIFS(FactBudget[BudsjettBelop],FactBudget[OrgKode],A7) -> 29250000 | D7: =SUMIFS(FactGL[Belop_signert],FactGL[OrgKode],A7) -> 28101060 | E7: =C7-D7 -> 1148940 | F7: =E7/C7 -> 0.03928 | G7: =SUMIFS(FactFTE[Aarsverk_UF],FactFTE[OrgKode],A7,FactFTE[DatoNokkel],202612) -> 34 | H7: =SUMIFS(FactFTE[Aarsverk_TA],FactFTE[OrgKode],A7,FactFTE[DatoNokkel],202612) -> 12 | I7: =G7+H7 -> 46 | J7: =IF(F7>=0,"🟢 Innenfor",IF(F7>=-5%,"🟡 Følg opp","🔴 Kritisk")) -> 🟢 Innenfor
A8: K13000 | B8: Økonomi | C8: =SUMIFS(FactBudget[BudsjettBelop],FactBudget[OrgKode],A8) -> 48403825 | D8: =SUMIFS(FactGL[Belop_signert],FactGL[OrgKode],A8) -> 49114510 | E8: =C8-D8 -> -710685 | F8: =E8/C8 -> -0.014682414 | G8: =SUMIFS(FactFTE[Aarsverk_UF],FactFTE[OrgKode],A8,FactFTE[DatoNokkel],202612) -> 75 | H8: =SUMIFS(FactFTE[Aarsverk_TA],FactFTE[OrgKode],A8,FactFTE[DatoNokkel],202612) -> 23 | I8: =G8+H8 -> 98 | J8: =IF(F8>=0,"🟢 Innenfor",IF(F8>=-5%,"🟡 Følg opp","🔴 Kritisk")) -> 🟡 Følg opp
A11: TILTAK — FORVENTET MOT REALISERT
A12: Tiltak | B12: Enhet | C12: Tiltaksnavn | D12: Forventet | E12: Realisert | F12: Grad | G12: Status | H12: Frist
A13: T001_HHU | B13: K10000 | C13: Frys i ikke-kritisk administrativ rekruttering (TA) | D13: 1200000 | E13: 950000 | F13: =E13/D13 -> 0.79166667 | G13: =IF(F13>=100%,"🟢 Fullført",IF(F13>=75%,"🟡 Følg opp","🔴 Kritisk gap")) -> 🟡 Følg opp | H13: 46387
A14: T002_HHU | B14: K13000 | C14: Økt overføring av vitenskapelig tid til BOA frikjøp (NFR/EU) | D14: 1800000 | E14: 1400000 | F14: =E14/D14 -> 0.77777778 | G14: =IF(F14>=100%,"🟢 Fullført",IF(F14>=75%,"🟡 Følg opp","🔴 Kritisk gap")) -> 🟡 Følg opp | H14: 46387
A15: T003_HHU | B15: K11000 | C15: Lønnsomhetskorrigering og prosjektkontroll på EVU001 (SRS 9) | D15: 800000 | E15: 450000 | F15: =E15/D15 -> 0.5625 | G15: =IF(F15>=100%,"🟢 Fullført",IF(F15>=75%,"🟡 Følg opp","🔴 Kritisk gap")) -> 🔴 Kritisk gap | H15: 46356
A16: T004_HHU | B16: K12000 | C16: Midlertidig vakanshold av professorhjemmel i Q2-Q3 | D16: 800000 | E16: 800000 | F16: =E16/D16 -> 1 | G16: =IF(F16>=100%,"🟢 Fullført",IF(F16>=75%,"🟡 Følg opp","🔴 Kritisk gap")) -> 🟢 Fullført | H16: 46295
A19: ANALYTISK KONKLUSJON
A20: Rettsvitenskap er hoveddriveren bak positivt sluttavvik (+1,15 MNOK), mens Økonomi har størst oppfølgingsbehov (–0,71 MNOK). Tiltakene har realisert 3,60 av 4,60 MNOK (78,3 %). De største gjenstående gapene ligger i BOA-frikjøp (0,40 MNOK) og EVU-kontroll (0,35 MNOK).
A24: RAG: budsjettavvik ≥0 % grønt, 0 til −5 % gult, <−5 % rødt | tiltak ≥100 % grønt, 75–99,9 % gult, <75 % rødt

Sheet Variance Actions
A1: DETALJERT AVVIKSANALYSE OG HANDLINGSPLAN
A2: HHU 2026 Latest Estimate | Fra totalavvik til rotårsak, tiltak og ansvar
A4: Netto sluttavvik | C4: Positive drivere | E4: Negative drivere | G4: Tiltaksgap | I4: Største risiko
A5: =SUM(FactBudget[BudsjettBelop])-SUM(FactGL[Belop_signert]) -> 522258 | C5: =SUMIF(F11:F21,">0",F11:F21) -> 2107632 | E5: =SUMIF(F11:F21,"<0",F11:F21) -> -1585374 | G5: =SUM(FactAction[ForventetInnsparingNOK])-SUM(FactAction[RealisertInnsparingNOK]) -> 1000000 | I5: K13000 lønn
A9: 1. AVVIKSDRIVERE — BUDSJETT MINUS LATEST ESTIMATE | J9: 2. MÅNEDSHOTSPOTS
A10: OrgKode | B10: Konto | C10: Driver | D10: Budsjett | E10: LE | F10: Avvik | G10: Avvik % | H10: RAG | J10: Måned | K10: Netto avvik | L10: Forklaring
A11: K13000 | B11: 5000 | C11: Fast lønn | D11: =SUMIFS(FactBudget[BudsjettBelop],FactBudget[OrgKode],A11,FactBudget[Konto],B11) -> 28074218 | E11: =SUMIFS(FactGL[Belop_signert],FactGL[OrgKode],A11,FactGL[Konto],B11) -> 29056814 | F11: =D11-E11 -> -982596 | G11: =IFERROR(F11/D11,IF(F11<0,-1,0)) -> -0.034999942 | H11: =IF(F11>=0,"🟢 Favorabel",IF(G11>=-5%,"🟡 Moderat","🔴 Kritisk")) -> 🟡 Moderat | J11: Juni | K11: -356048 | L11: Feriepenger + lønnseffekt
A12: K12000 | B12: 5000 | C12: Fast lønn | D12: =SUMIFS(FactBudget[BudsjettBelop],FactBudget[OrgKode],A12,FactBudget[Konto],B12) -> 16965000 | E12: =SUMIFS(FactGL[Belop_signert],FactGL[OrgKode],A12,FactGL[Konto],B12) -> 16286400 | F12: =D12-E12 -> 678600 | G12: =IFERROR(F12/D12,IF(F12<0,-1,0)) -> 0.04 | H12: =IF(F12>=0,"🟢 Favorabel",IF(G12>=-5%,"🟡 Moderat","🔴 Kritisk")) -> 🟢 Favorabel | J12: September | K12: -278427 | L12: EVU001-avsetning + AACSB
A13: K13000 | B13: 5080 | C13: Feriepenger | D13: =SUMIFS(FactBudget[BudsjettBelop],FactBudget[OrgKode],A13,FactBudget[Konto],B13) -> 3388268 | E13: =SUMIFS(FactGL[Belop_signert],FactGL[OrgKode],A13,FactGL[Konto],B13) -> 2980829 | F13: =D13-E13 -> 407439 | G13: =IFERROR(F13/D13,IF(F13<0,-1,0)) -> 0.12024993 | H13: =IF(F13>=0,"🟢 Favorabel",IF(G13>=-5%,"🟡 Moderat","🔴 Kritisk")) -> 🟢 Favorabel | J13: Desember | K13: 120576 | L13: Normal Q4-prognose
A14: K11000 | B14: 5080 | C14: Feriepenger | D14: =SUMIFS(FactBudget[BudsjettBelop],FactBudget[OrgKode],A14,FactBudget[Konto],B14) -> 2695000 | E14: =SUMIFS(FactGL[Belop_signert],FactGL[OrgKode],A14,FactGL[Konto],B14) -> 2290746 | F14: =D14-E14 -> 404254 | G14: =IFERROR(F14/D14,IF(F14<0,-1,0)) -> 0.15000148 | H14: =IF(F14>=0,"🟢 Favorabel",IF(G14>=-5%,"🟡 Moderat","🔴 Kritisk")) -> 🟢 Favorabel | J14: Øvrige måneder | K14: 1013193 | L14: Stabile, hovedsakelig favorable
A15: K12000 | B15: 5080 | C15: Feriepenger | D15: =SUMIFS(FactBudget[BudsjettBelop],FactBudget[OrgKode],A15,FactBudget[Konto],B15) -> 2047500 | E15: =SUMIFS(FactGL[Belop_signert],FactGL[OrgKode],A15,FactGL[Konto],B15) -> 1670760 | F15: =D15-E15 -> 376740 | G15: =IFERROR(F15/D15,IF(F15<0,-1,0)) -> 0.184 | H15: =IF(F15>=0,"🟢 Favorabel",IF(G15>=-5%,"🟡 Moderat","🔴 Kritisk")) -> 🟢 Favorabel
A16: K11000 | B16: 7790 | C16: EVU001 tapsavsetning | D16: =SUMIFS(FactBudget[BudsjettBelop],FactBudget[OrgKode],A16,FactBudget[Konto],B16) -> 0 | E16: =SUMIFS(FactGL[Belop_signert],FactGL[OrgKode],A16,FactGL[Konto],B16) -> 350000 | F16: =D16-E16 -> -350000 | G16: =IFERROR(F16/D16,IF(F16<0,-1,0)) -> -1 | H16: =IF(F16>=0,"🟢 Favorabel",IF(G16>=-5%,"🟡 Moderat","🔴 Kritisk")) -> 🔴 Kritisk
A17: K10000 | B17: 5080 | C17: Feriepenger | D17: =SUMIFS(FactBudget[BudsjettBelop],FactBudget[OrgKode],A17,FactBudget[Konto],B17) -> 980000 | E17: =SUMIFS(FactGL[Belop_signert],FactGL[OrgKode],A17,FactGL[Konto],B17) -> 833001 | F17: =D17-E17 -> 146999 | G17: =IFERROR(F17/D17,IF(F17<0,-1,0)) -> 0.14999898 | H17: =IF(F17>=0,"🟢 Favorabel",IF(G17>=-5%,"🟡 Moderat","🔴 Kritisk")) -> 🟢 Favorabel
A18: K13000 | B18: 5400 | C18: Arbeidsgiveravgift | D18: =SUMIFS(FactBudget[BudsjettBelop],FactBudget[OrgKode],A18,FactBudget[Konto],B18) -> 3872306 | E18: =SUMIFS(FactGL[Belop_signert],FactGL[OrgKode],A18,FactGL[Konto],B18) -> 4007834 | F18: =D18-E18 -> -135528 | G18: =IFERROR(F18/D18,IF(F18<0,-1,0)) -> -0.0349993 | H18: =IF(F18>=0,"🟢 Favorabel",IF(G18>=-5%,"🟡 Moderat","🔴 Kritisk")) -> 🟡 Moderat
A19: K12000 | B19: 5400 | C19: Arbeidsgiveravgift | D19: =SUMIFS(FactBudget[BudsjettBelop],FactBudget[OrgKode],A19,FactBudget[Konto],B19) -> 2340000 | E19: =SUMIFS(FactGL[Belop_signert],FactGL[OrgKode],A19,FactGL[Konto],B19) -> 2246400 | F19: =D19-E19 -> 93600 | G19: =IFERROR(F19/D19,IF(F19<0,-1,0)) -> 0.04 | H19: =IF(F19>=0,"🟢 Favorabel",IF(G19>=-5%,"🟡 Moderat","🔴 Kritisk")) -> 🟢 Favorabel
A20: K10000 | B20: 6700 | C20: AACSB konsulentkostnad | D20: =SUMIFS(FactBudget[BudsjettBelop],FactBudget[OrgKode],A20,FactBudget[Konto],B20) -> 420000 | E20: =SUMIFS(FactGL[Belop_signert],FactGL[OrgKode],A20,FactGL[Konto],B20) -> 479500 | F20: =D20-E20 -> -59500 | G20: =IFERROR(F20/D20,IF(F20<0,-1,0)) -> -0.14166667 | H20: =IF(F20>=0,"🟢 Favorabel",IF(G20>=-5%,"🟡 Moderat","🔴 Kritisk")) -> 🔴 Kritisk
A21: K11000 | B21: 5100 | C21: Midlertidig lønn / timelærere | D21: =SUMIFS(FactBudget[BudsjettBelop],FactBudget[OrgKode],A21,FactBudget[Konto],B21) -> 1540000 | E21: =SUMIFS(FactGL[Belop_signert],FactGL[OrgKode],A21,FactGL[Konto],B21) -> 1597750 | F21: =D21-E21 -> -57750 | G21: =IFERROR(F21/D21,IF(F21<0,-1,0)) -> -0.0375 | H21: =IF(F21>=0,"🟢 Favorabel",IF(G21>=-5%,"🟡 Moderat","🔴 Kritisk")) -> 🟡 Moderat
A24: 3. PRIORITERT HANDLINGSPLAN
A25: Prioritet | B25: Område | C25: Rotårsak / observasjon | D25: Anbefalt handling | E25: Eier | F25: Frist | G25: Brutto gap | H25: Forventet effekt | I25: KPI / kontrollpunkt | J25: RAG | K25: Beslutning nå | L25: Oppfølging
A26: 1 | B26: K13000 Økonomi | C26: Fast lønn og AGA gir 1,12 MNOK merforbruk før feriepengeeffekt. | D26: Lås nyansettelser uten finansiering; realiser resterende BOA-frikjøp og månedlig avstem lønnsfil mot UBW. | E26: Instituttleder Økonomi | F26: 46356 | G26: 1118124 | H26: 710685 | I26: Månedlig lønnsavvik ≤ 0; T002 realisering 100 % | J26: 🔴 Høy | K26: Godkjenn lønns- og BOA-tiltaksplan | L26: Ukentlig til gap <0,2 MNOK
A27: 2 | B27: K11000 Ledelse/innovasjon | C27: EVU001 tapsavsetning 0,35 MNOK og 0,06 MNOK ekstra midlertidig lønn. | D27: Fullfør EVU-lønnsomhetsanalyse, revider kontraktsmargin og stopp nye leveranser uten dokumentert dekningsbidrag. | E27: Instituttleder Ledelse | F27: 46326 | G27: 407750 | H27: 350000 | I27: T003 realisering 100 %; EVU DB ≥ 0 | J27: 🔴 Høy | K27: Beslutt korrigert EVU-scope/pris | L27: Annenhver uke
A28: 3 | B28: K12000 Rettsvitenskap | C28: Vakans og lavere lønnsrelaterte kostnader gir 1,15 MNOK mindreforbruk. | D28: Beskytt besparelsen; tillat bare kritiske ansettelser og vurder faglig kapasitetsrisiko før permanent reduksjon. | E28: Instituttleder Rettsvitenskap | F28: 46371 | G28: 0 | H28: 1148940 | I28: VAC ≥ +0,8 MNOK og forsvarlig undervisningskapasitet | J28: 🟢 Sikre | K28: Bekreft rekrutteringsplan 2027 | L28: Månedlig
A29: 4 | B29: K10000 Administrasjon | C29: AACSB-konsulentkostnad er 0,06 MNOK over plan, delvis motvirket av lavere feriepenger. | D29: Fastsett gjenværende AACSB-scope og innfør endringsgodkjenning for tilleggstimer. | E29: Fakultetsdirektør | F29: 46310 | G29: 59500 | H29: 59500 | I29: Ingen nye ikke-godkjente konsulenttimer | J29: 🟡 Moderat | K29: Godkjenn kostnadstak | L29: Ved hver bestilling
A30: 5 | B30: Tiltaksportefølje | C30: Samlet urealisert tiltaksgap er 1,00 MNOK; T003 har lavest grad på 56,3 %. | D30: Etabler én samlet lukkeplan for T001–T003 med ukentlig eierstatus, beløpsbevis og eskalering ved manglende fremdrift. | E30: Fakultetsdirektør | F30: 46302 | G30: 1000000 | H30: 1000000 | I30: Realisert grad ≥ 90 % innen november | J30: 🔴 Høy | K30: Mandater ukentlig tiltakstavle | L30: Ukentlig
A33: LEDELSESVURDERING
A34: Nettoresultatet er positivt, men robustheten er svak: 1,15 MNOK i vakansbesparelse ved Rettsvitenskap dekker i stor grad lønnsmerforbruket i Økonomi og avvik knyttet til EVU/AACSB. Ledelsen bør derfor ikke tolke +0,52 MNOK som strukturelt handlingsrom. Første prioritet er å lukke lønns- og BOA-gapet i K13000; andre prioritet er å stoppe videre marginerosjon i EVU001. Besparelsen i K12000 bør beholdes som buffer inntil disse risikoene er lukket.

Sheet 2027 Plan Report
A1: HHU BUDSJETT- OG KAPASITETSPLAN 2027
A2: Driverbasert plan | økonomi, bemanning, utdanning og tiltak
A4: INNTEKTER | D4: KOSTNADER | G4: NETTO RESULTAT | J4: LØNNSANDEL | M4: STUDENTER
A5: {=SUM(SUMIFS(FactBudget_2027[BudsjettBelop],FactBudget_2027[Konto],{3900,3670,3600,3630,3400,3420}))} -> 2.8607e+08 | D5: =SUM(FactBudget_2027[BudsjettBelop])-A5 -> 2.82e+08 | G5: =A5-D5 -> 4069999.7 | J5: {=SUM(SUMIFS(FactBudget_2027[BudsjettBelop],FactBudget_2027[Konto],{5000,5400}))/A5} -> 0.66766875 | M5: =SUMIFS(FactStudents_2027[RegistrerteStudenter],FactStudents_2027[DatoNokkel],20271031) -> 3450
A7: 🔴 2,0 MNOK under dokumentert ramme | D7: 282,0 MNOK plan | G7: 🟡 Positiv, men 2,0 MNOK under mål | J7: 🔴 Over mål 64,5 % | M7: 3 153 SPE60 | 22,3 stud./UF
A10: ØKONOMI OG KAPASITET PER ENHET
A11: OrgKode | B11: Enhet | C11: Inntekter | D11: Kostnader | E11: Netto | F11: ÅV | G11: UF-ÅV | H11: Studenter | I11: SPE60 | K11: Tiltak | L11: Enhet | M11: Effekt | N11: Status | O11: Beslutningsdriver
A12: K10000 | B12: Fakultetsadministrasjon & Felles | C12: {=SUM(SUMIFS(FactBudget_2027[BudsjettBelop],FactBudget_2027[OrgKode],A12,FactBudget_2027[Konto],{3900,3670,3600,3630,3400,3420}))} -> 14769850 | D12: =SUMIFS(FactBudget_2027[BudsjettBelop],FactBudget_2027[OrgKode],A12)-C12 -> 14500000 | E12: =C12-D12 -> 269850 | F12: =SUMIFS(FactFTE_2027[Aarsverk_Totalt],FactFTE_2027[OrgKode],A12,FactFTE_2027[DatoNokkel],20271231) -> 28.95 | G12: =SUMIFS(FactFTE_2027[Aarsverk_UF],FactFTE_2027[OrgKode],A12,FactFTE_2027[DatoNokkel],20271231) -> 5 | H12: =SUMIFS(FactStudents_2027[RegistrerteStudenter],FactStudents_2027[OrgKode],A12,FactStudents_2027[DatoNokkel],20271031) -> 0 | I12: =SUMIFS(FactStudents_2027[SPE60],FactStudents_2027[OrgKode],A12,FactStudents_2027[DatoNokkel],20271031) -> 0 | K12: T001 | L12: K10000 | M12: 1800000 | N12: 🟢 Gjennomført | O12: Vakans / lønn
A13: K11000 | B13: Ledelse og innovasjon | C13: {=SUM(SUMIFS(FactBudget_2027[BudsjettBelop],FactBudget_2027[OrgKode],A13,FactBudget_2027[Konto],{3900,3670,3600,3630,3400,3420}))} -> 80000000 | D13: =SUMIFS(FactBudget_2027[BudsjettBelop],FactBudget_2027[OrgKode],A13)-C13 -> 78000000 | E13: =C13-D13 -> 2000000 | F13: =SUMIFS(FactFTE_2027[Aarsverk_Totalt],FactFTE_2027[OrgKode],A13,FactFTE_2027[DatoNokkel],20271231) -> 60.79 | G13: =SUMIFS(FactFTE_2027[Aarsverk_UF],FactFTE_2027[OrgKode],A13,FactFTE_2027[DatoNokkel],20271231) -> 45 | H13: =SUMIFS(FactStudents_2027[RegistrerteStudenter],FactStudents_2027[OrgKode],A13,FactStudents_2027[DatoNokkel],20271031) -> 1150 | I13: =SUMIFS(FactStudents_2027[SPE60],FactStudents_2027[OrgKode],A13,FactStudents_2027[DatoNokkel],20271031) -> 1050 | K13: T002 | L13: K13000 | M13: 1500000 | N13: 🟢 I rute | O13: Faglig reallokering
A14: K12000 | B14: Rettsvitenskap | C14: {=SUM(SUMIFS(FactBudget_2027[BudsjettBelop],FactBudget_2027[OrgKode],A14,FactBudget_2027[Konto],{3900,3670,3600,3630,3400,3420}))} -> 62000000 | D14: =SUMIFS(FactBudget_2027[BudsjettBelop],FactBudget_2027[OrgKode],A14)-C14 -> 61000000 | E14: =C14-D14 -> 999999.96 | F14: =SUMIFS(FactFTE_2027[Aarsverk_Totalt],FactFTE_2027[OrgKode],A14,FactFTE_2027[DatoNokkel],20271231) -> 48.25 | G14: =SUMIFS(FactFTE_2027[Aarsverk_UF],FactFTE_2027[OrgKode],A14,FactFTE_2027[DatoNokkel],20271231) -> 38 | H14: =SUMIFS(FactStudents_2027[RegistrerteStudenter],FactStudents_2027[OrgKode],A14,FactStudents_2027[DatoNokkel],20271031) -> 850 | I14: =SUMIFS(FactStudents_2027[SPE60],FactStudents_2027[OrgKode],A14,FactStudents_2027[DatoNokkel],20271031) -> 788 | K14: T003 | L14: K11000 | M14: 1400000 | N14: 🟢 I rute | O14: EVU-inntekt
A15: K13000 | B15: Økonomi | C15: {=SUM(SUMIFS(FactBudget_2027[BudsjettBelop],FactBudget_2027[OrgKode],A15,FactBudget_2027[Konto],{3900,3670,3600,3630,3400,3420}))} -> 1.2930015e+08 | D15: =SUMIFS(FactBudget_2027[BudsjettBelop],FactBudget_2027[OrgKode],A15)-C15 -> 1.285e+08 | E15: =C15-D15 -> 800149.68 | F15: =SUMIFS(FactFTE_2027[Aarsverk_Totalt],FactFTE_2027[OrgKode],A15,FactFTE_2027[DatoNokkel],20271231) -> 83.95 | G15: =SUMIFS(FactFTE_2027[Aarsverk_UF],FactFTE_2027[OrgKode],A15,FactFTE_2027[DatoNokkel],20271231) -> 67 | H15: =SUMIFS(FactStudents_2027[RegistrerteStudenter],FactStudents_2027[OrgKode],A15,FactStudents_2027[DatoNokkel],20271031) -> 1450 | I15: =SUMIFS(FactStudents_2027[SPE60],FactStudents_2027[OrgKode],A15,FactStudents_2027[DatoNokkel],20271031) -> 1315 | K15: T004 | L15: K13000 | M15: 1800000 | N15: 🟢 I rute | O15: TDI / BOA
A17: Diagrammet viser nivåer (nøytral palett); RAG brukes på nettoresultat og måloppnåelse i tabell/KPI-kort.
A18: Inntekter og kostnader per enhet | K18: BESLUTNINGSSTØTTE
K19: 1. Avklar manglende 2,0 MNOK inntekt før budsjettet publiseres. 2. Konto-basert lønnsandel er 66,8 %, over mål 64,5 %; avstem mot FTE-filens 63,9 %. 3. Beskytt tiltak T003/T004: 3,2 MNOK inntektsvekst fra EVU og BOA er nødvendig for handlingsrommet. 4. K13000 bærer 45 % av inntektene og krever tett prosjekt- og kapasitetsstyring.
A35: RAG: grønt = mål oppfylt | gult = moderat avvik som krever oppfølging | rødt = målbrudd eller kritisk datagap

Sheet Budget Process 2027
A1: BUDSJETTPROSESS 2027 — STYRING, ANALYSE OG BESLUTNINGER
A2: Handelshøyskolen ved UiA | Fra rammeforutsetninger til systemfrys og løpende prognose
A4: INNTEKTER | D4: KOSTNADER | G4: RESULTAT | J4: LØNNSANDEL | M4: ÅRSVERK
A5: {=SUM(SUMIFS(FactBudget_2027[BudsjettBelop],FactBudget_2027[Konto],{3900,3670,3600,3630,3400,3420}))} -> 2.8607e+08 | D5: =SUM(FactBudget_2027[BudsjettBelop])-A5 -> 2.82e+08 | G5: =A5-D5 -> 4069999.7 | J5: {=SUM(SUMIFS(FactBudget_2027[BudsjettBelop],FactBudget_2027[Konto],{5000,5400}))/A5} -> 0.66766875 | M5: =SUMIFS(FactFTE_2027[Aarsverk_Totalt],FactFTE_2027[DatoNokkel],20271231) -> 221.94
A7: 🔴 2,0 MNOK under dokumentert ramme | D7: 282,0 MNOK | G7: 🟡 Positivt, men under målet | J7: 🟡 66,8 % mot mål ≤64,5 % | M7: 230 planlagt | 3,5 % vakans
A10: 1. PROSESSKART OG BESLUTNINGSPORTER
A11: Fase | B11: Tidspunkt | C11: Hovedspørsmål | D11: Nøkkelaktiviteter | E11: Datagrunnlag | F11: Ansvarlig | G11: Leveranse | H11: Beslutningsport | I11: Status | J11: RAG | K11: Kontroll | L11: Avhengighet | M11: Neste handling | N11: Frist
A12: 1 | B12: 46266 | C12: Hva er bindende ramme? | D12: Avstem KD-/UiA-ramme, kontoplan og versjon | E12: Tildelingsbrev, BUD2026 | F12: Senior Controller | G12: Rammebrev og forutsetningsnotat | H12: Ramme godkjent | I12: Nesten ferdig | J12: 🟡 | K12: Én signert rammeversjon | L12: Sentral økonomi | M12: Avklar 2,0 MNOK inntektsgap | N12: 46302
A13: 2 | B13: Sep–okt 2026 | C13: Hvilke drivere forklarer 2027? | D13: Valider SPE60-lag, lønn, vakans, TDI/BOA, EVU og Capex | E13: FS, HR, prosjektportefølje | F13: Controller + fagledelse | G13: Dokumentert driverbok | H13: Drivere godkjent | I13: Krever avstemming | J13: 🔴 | K13: Kilde, eier og beløp per driver | L13: HR, FS og prosjektøkonomi | M13: Avstem lønnsandel 66,8/63,9/64,2 % | N13: 46310
A14: 3 | B14: Okt 2026 | C14: Er enhetsplanene realistiske? | D14: Instituttvise bemannings-, undervisnings- og driftsplaner | E14: Budsjett- og FTE-tabeller | F14: Instituttledere | G14: Fire enhetsbudsjetter | H14: Enhetsleder sign-off | I14: Datagrunnlag klart | J14: 🟢 | K14: Budsjett = bemanning + aktivitet | L14: Godkjente stillingshjemler | M14: Dokumenter lokale forutsetninger | N14: 46318
A15: 4 | B15: Okt–nov 2026 | C15: Tåler planen risiko og scenarioer? | D15: Konsolidering, sensitiviteter, langtidsprognose og reserveanalyse | E15: BUD2027 og tiltak | F15: Senior Controller | G15: Scenario- og risikorapport | H15: Ledelsesgjennomgang | I15: Åpent gap | J15: 🟡 | K15: Resultat, lønnsandel og RAG | L15: Fullført fase 1–3 | M15: Kjør downside på inntekt og BOA | N15: 46332
A16: 5 | B16: Nov–des 2026 | C16: Kan baseline låses? | D16: Kvalitetssikring, styresak, godkjenning og UBW-frys | E16: Budsjettnotat og kontrolliste | F16: Fakultetsdirektør / styret | G16: Godkjent og låst BUD2027 | H16: Formelt vedtak | I16: Ikke klar | J16: 🔴 | K16: Ingen uforklarte differanser | L16: Lukket inntekts- og lønnsgap | M16: Utsett frys til avstemming er signert | N16: 46371
A17: 6 | B17: Jan–des 2027 | C17: Leverer vi mot vedtatt plan? | D17: Månedlig actual vs budget, LE, RAG og tiltak | E17: FactGL, FactAction, Power BI | F17: Controller + enhetsledere | G17: Månedsrapport og revidert LE | H17: Månedlig ledermøte | I17: Planlagt | J17: ⚪ | K17: Avvik, forecast og tiltak | L17: Låst BUD2027 | M17: Etabler rapportkalender M01–M12 | N17: 46397
P18: Rød = uløst avvik | Grønn = avstemt
A20: 2. DRIVERANALYSE OG MODELLAVSTEMMING
A21: Driver | B21: Mekanisme | C21: Kvantifisering | D21: Budsjetteffekt | E21: Risiko | F21: Kontrollaktivitet | G21: Eier | H21: RAG | J21: Avstemming | K21: Modellverdi | L21: Referanse | M21: Differanse | N21: Konklusjon
A22: KD/SPE60 2-års lag | B22: 2025-produksjon styrer 2027-utbetaling | C22: +33 SPE60 × 54 550 kr | D22: +1,80 MNOK inntekt | E22: Lav sats kan gi negativ marginaløkonomi | F22: Avstem FS mot finansieringsgrunnlag | G22: Studiedirektør / Controller | H22: 🟡 | J22: Inntekter | K22: 2.8607e+08 | L22: 288070000 | M22: -2000000.2 | N22: Må avklares før frys
A23: Basisbevilgning | B23: Eksisterende volum ligger i fast basis | C23: 251,8 MNOK konto 3900 | D23: Stabiliserer inntektene | E23: Feil rammeversjon påvirker hele modellen | F23: Signert rammebrev og versjonskontroll | G23: Fakultetsdirektør | H23: 🔴 | J23: Kostnader | K23: 2.82e+08 | L23: 282000000 | M23: 0.12 | N23: Avstemt
A24: Bemanning og vakans | B24: 230 planlagte ÅV med 3,5 % vakans | C24: 221,94 effektive ÅV | D24: Reduserer lønnsbelastning | E24: Tidligere oppstart øker kostnaden | F24: Stillingsregister og månedlig lønnsbro | G24: HR + instituttledere | H24: 🔴 | J24: Netto resultat | K24: 4069999.7 | L24: 6070000 | M24: -2000000.3 | N24: Følger inntektsgapet
A25: BOA/TDI | B25: Frikjøp flytter lønn og gir overhead | C25: T004: 1,80 MNOK; ca. 22 % OH | D25: Bedrer BFV-handlingsrom | E25: Underdekning subsidierer prosjekter | F25: Prosjektkalkyle og dekningsgradsport | G25: Forskningsleder | H25: 🟡 | J25: Lønnsandel, konto | K25: 0.66766875 | L25: 0.645 | M25: 0.022668753 | N25: 2,27 prosentpoeng over mål
A26: EVU/SRS 9 | B26: Inntekt etter fullføringsgrad; tap avsettes straks | C26: T003: 1,40 MNOK | D26: Øker ekstern inntekt | E26: Marginerosjon og tapsavsetning | F26: Kontraktsmargin og månedlig EAC | G26: Instituttleder Ledelse | H26: 🟡 | J26: Effektive ÅV | K26: 221.94 | L26: 230 | M26: -8.06 | N26: Forklares av 3,5 % vakans
A27: Capex / 5 %-regel | B27: Overskudd bindes til investeringer | C27: 32,0 MNOK konto 1250 | D27: Beskytter handlingsrom | E27: Udisponerte reserver kan trekkes inn | F27: Godkjent investeringsplan | G27: Fakultetsdirektør | H27: 🟢
A30: 3. STYRINGSMODELL OG KONTROLLRAMMEVERK
A31: Nivå | B31: Beslutning / ansvar | C31: Frekvens | D31: Input | E31: Kontrollbevis | F31: Eskalering | G31: Output | I31: Kontrollpunkt | J31: Grønn | K31: Gul | L31: Rød | M31: Handling | N31: Rapport
A32: Fakultetsstyret | B32: Godkjenner ramme, resultatmål og investeringsplan | C32: Årlig | D32: Styresak BUD2027 | E32: Vedtaksprotokoll | F32: Uforklart gap eller negativt scenario | G32: Godkjent budsjett | I32: Netto resultat | J32: ≥6,07 MNOK | K32: 0–6,07 MNOK | L32: <0 | M32: Oppdater LE og tiltak | N32: Månedlig
A33: Fakultetsdirektør | B33: Prioriterer bemanning, tiltak og reservebruk | C33: Månedlig | D33: LE, RAG og tiltak | E33: Signert tiltakslogg | F33: Rød status eller >5 % avvik | G33: Ledelsesbeslutning | I33: Lønnsandel | J33: ≤64,5 % | K33: 64,5–67,0 % | L33: >67,0 % | M33: Bemannings- og vakansgjennomgang | N33: Månedlig
A34: Senior Controller | B34: Eier modell, avstemming, konsolidering og forecast | C34: Månedlig | D34: UBW, FS, HR og prosjekt | E34: Avstemmingspakke | F34: Manglende data / versjonsbrudd | G34: Månedsrapport og LE | I34: Budsjettavvik | J34: ≥0 % | K34: 0 til −5 % | L34: <−5 % | M34: Eierforklaring og korrigerende tiltak | N34: Månedlig
A35: Instituttledere | B35: Eier lokale forutsetninger og tiltak | C35: Månedlig | D35: Bemanning, aktivitet og prosjekt | E35: Kommentar og handlingsplan | F35: Gult/rødt enhetsavvik | G35: Oppdatert prognose | I35: Tiltaksgrad | J35: ≥100 % | K35: 75–99,9 % | L35: <75 % | M35: Lukkeplan og eskalering | N35: Ukentlig/månedlig
A36: Prosjekt-/studieledere | B36: Validerer BOA, EVU og studentdrivere | C36: Månedlig/tertial | D36: Prosjekt-EAC og SPE60 | E36: Kalkyle / FS-uttrekk | F36: Negativ margin eller produksjonsfall | G36: Driveroppdatering | I36: BOA/EVU-margin | J36: ≥mål | K36: 0–mål | L36: Negativ | M36: Stopp, reprising eller omfangsendring | N36: Månedlig
I37: Datakvalitet | J37: Ingen gap | K37: Dokumentert midlertidig gap | L37: Uforklart gap | M37: Stopp systemfrys | N37: Ved milepæl
A39: 4. PRIORITERT LUKKEPLAN FØR SYSTEMFRYS
A40: Prioritet | B40: Avvik / risiko | C40: Handling | D40: Eier | E40: Frist | F40: Bevis / ferdigkriterium | G40: Konsekvens hvis ikke lukket | H40: RAG
A41: 1 | B41: 2,0 MNOK manglende inntektslinje | C41: Avstem rammebrev, konto og enhet; korriger kilden eller dokumenter formelt vedtak | D41: Senior Controller / sentral økonomi | E41: 46302 | F41: Modellinntekt = signert ramme | G41: Resultat og styresak blir feil | H41: 🔴
A42: 2 | B42: Lønnsandel 66,8 % mot mål 64,5 % | C42: Avstem konto-basert modell mot FTE-fil og budsjettnotat; dokumenter definisjon og beslutning | D42: Controller / HR | E42: 46310 | F42: Én godkjent lønnsdefinisjon og bro | G42: Feil RAG og svak bemanningsstyring | H42: 🔴
A43: 3 | B43: BOA/TDI-avhengighet | C43: Valider 22 % overhead, finansierte frikjøp og prosjektmargin før stillingsdisponering | D43: Forskningsleder | E43: 46318 | F43: Signerte prosjektkalkyler og frikjøpsplan | G43: BFV subsidierer ekstern aktivitet | H43: 🟡
A44: 4 | B44: EVU/SRS 9-risiko | C44: Krev positiv kontraktsmargin og månedlig EAC før nye leveranser | D44: Instituttleder Ledelse | E44: 46326 | F44: Godkjent kalkyle og tapsrisiko = 0 | G44: Tapsavsetning reduserer resultatet | H44: 🟡
A45: 5 | B45: Formålskapital / 5 %-regel | C45: Knytt overskuddet til vedtatte flerårige investeringer med milepæler | D45: Fakultetsdirektør | E45: 46341 | F45: Godkjent investeringsplan | G45: Risiko for passiv reserve/inndragning | H45: 🟢
A46: 6 | B46: Baseline og sporbarhet | C46: Kjør komplett kontrolliste, godkjenning og lås BUD2027 først etter lukking | D46: Senior Controller | E46: 46371 | F46: Signert kontrollpakke og låst versjon | G46: Ustabil baseline og svakt revisjonsspor | H46: 🔴
A49: SAMLET ANALYSE OG ANBEFALING
A50: Budsjettprosessen er riktig bygget som en driverbasert styringsprosess: ekstern ramme og SPE60-etterslep oversettes til inntekter, bemanning og aktivitet; instituttplanene konsolideres; risiko og langtidsvirkning testes; deretter godkjennes og låses baseline før månedlig oppfølging. Dagens modell er likevel ikke klar for endelig systemfrys. Inntektsrammen er 2,0 MNOK lavere enn dokumentert mål, og konto-basert lønnsandel på 66,8 % avviker fra både målet på 64,5 % og FTE-filens 63,9 %. Anbefalingen er å stoppe ved beslutningsport 5 til disse forholdene er signert avklart. Deretter bør BUD2027 låses sammen med investeringsplan, tiltakseiere og månedlig RAG-rapportering.

Sheet Forecast Methods 2027
A1: PROGNOSEMETODIKK 2027 — FRA BUDSJETT TIL LATEST ESTIMATE
A2: Metodebibliotek for månedlig prognose: Actual YTD + gjenstående estimat (ETC) = helårsprognose (EAC)
A4: SAMLET PLANVOLUM | E4: ACTUAL YTD | I4: ETC | M4: EAC / LE
A5: =SUM(FactBudget_2027[BudsjettBelop]) -> 5.6807e+08 | E5: Bokført hittil | I5: Gjenstående estimat | M5: Actual YTD + ETC
A7: 568,07 MNOK = 286,07 inntekter + 282,00 kostnader | E7: Hentes fra FactGL når 2027-regnskap foreligger | I7: Driverbasert prognose for resterende måneder | M7: Ny forventet helårsverdi
A10: 1. HVORDAN HVER BUDSJETTPOST PROGNOSTISERES
A11: Prioritet | B11: Budsjettpost | C11: Konto / tabell | D11: 2027 baseline | E11: Prognosemetode | F11: Driver / input | G11: Operativ beregning | H11: Oppdatering | I11: Datakilde | J11: Eier | K11: Best case | L11: Base case | M11: Downside | N11: RAG-kontroll
A12: Høy | B12: Basisbevilgning | C12: 3900 | D12: 2.5180015e+08 | E12: Fast ramme + vedtatte endringer | F12: Tildelingsbrev og rammeendringer | G12: Siste godkjente ramme + signerte endringer | H12: Ved rammeendring | I12: KD/UiA rammebrev | J12: Senior Controller | K12: 253800150 | L12: 251800150 | M12: 249800150 | N12: Avvik mot signert ramme
A13: Middels | B13: SPE60-resultatinntekt | C13: FactStudents_2027 | D13: 1800150 | E13: Volum × sats med 2-års lag | F13: Endelig 2025 SPE60-vekst og KD-sats | G13: SPE60-vekst × 54 550 kr | H13: Tertial | I13: FS + KD-sats | J13: Studiedirektør | K13: 2072900 | L13: 1800150 | M13: 1527400 | N13: Avvik >5 % fra godkjent volum
A14: Høy | B14: NFR/EU og TDI | C14: 3400/3420 | D14: 20000000 | E14: Prosjekt-for-prosjekt EAC | F14: Kontrakt, fremdrift, frikjøp og overhead | G14: Bokført inntekt + gjenstående finansiert aktivitet | H14: Månedlig | I14: Prosjektregnskap | J14: Forskningsleder | K14: 22000000 | L14: 20000000 | M14: 17000000 | N14: Negativ margin / OH under mål
A15: Høy | B15: EVU-inntekter | C15: 3600/3630 | D15: 13000000 | E15: Kontraktsbasert EAC | F15: Kontraktsverdi, fullføringsgrad og kostnad til ferdigstillelse | G15: Opptjent inntekt + gjenstående leveranseverdi | H15: Månedlig | I15: EVU-kontrakter | J15: Instituttleder Ledelse | K15: 14500000 | L15: 13000000 | M15: 11000000 | N15: Negativ EAC-margin
A16: Høy | B16: Fast lønn | C16: 5000 | D16: 1.554e+08 | E16: Ansatt-for-ansatt prognose | F16: Årslønn, stillingsprosent, start/slutt og lønnsoppgjør | G16: Bokført lønn + månedslønn × resterende måneder | H16: Månedlig | I16: HR/UBW lønn | J16: HR + instituttledere | K16: 151500000 | L16: 155400000 | M16: 160000000 | N16: Lønnsandel >67 %
A17: Høy | B17: Arbeidsgiveravgift | C17: 5400 | D17: 35600000 | E17: Påslag på prognostisert lønn | F17: Gjeldende AGA-sats og avgiftsgrunnlag | G17: Prognostisert lønnsgrunnlag × AGA-sats | H17: Månedlig | I17: Lønnsprognose | J17: Senior Controller | K17: 34700000 | L17: 35600000 | M17: 36700000 | N17: Avvik følger lønn
A18: Høy | B18: Vakans og rekruttering | C18: FactFTE_2027 | D18: 221.94 | E18: Stilling-for-stilling kapasitetsplan | F18: Faktisk ledighet og forventet tiltredelse | G18: Budsjettert ÅV − vakans frem til realistisk start | H18: Månedlig | I18: HR stillingsregister | J18: HR + instituttledere | K18: 219 | L18: 221.94 | M18: 226 | N18: Vakans lavere enn plan
A19: Middels | B19: Driftskostnader | C19: 6300/6420/6700/7130 | D19: 59000000 | E19: Run-rate + kjente forpliktelser | F19: Faste avtaler, forbruk, pris og engangskostnader | G19: Bokført + åpne PO + normalisert månedsforbruk | H19: Månedlig | I19: UBW / innkjøp | J19: Budsjettansvarlige | K19: 57000000 | L19: 59000000 | M19: 62000000 | N19: Helårsavvik <−5 %
A20: Middels | B20: Investeringer / Capex | C20: 1250 | D20: 32000000 | E20: Milepælsbasert prognose | F20: Kontrakt, anskaffelse, leveranse og aktivering | G20: Bokført + kontraktsfestet beløp per milepæl | H20: Månedlig | I20: Investeringsplan | J20: Fakultetsdirektør | K20: 30000000 | L20: 32000000 | M20: 34000000 | N20: Forsinkelse / ubundet reserve
A21: Høy | B21: Tiltak T001–T004 | C21: FactAction_2027 | D21: 6500000 | E21: Tiltakseier-estimat | F21: Realisert effekt, sannsynlighet og timing | G21: Realisert + sannsynlig gjenstående effekt | H21: Ukentlig/månedlig | I21: FactAction_2027 | J21: Tiltakseiere | K21: 6500000 | L21: 5850000 | M21: 4550000 | N21: Grad <75 %
A22: Beregnet | B22: Netto resultat | C22: Inntekter − kostnader | D22: 4069999.7 | E22: Residualberegning | F22: Alle inntekts- og kostnadsprognoser | G22: Prognostiserte inntekter − prognostiserte kostnader | H22: Månedlig | I22: Samlet modell | J22: Senior Controller | K22: 11372850 | L22: 4069999.7 | M22: -11127250 | N22: <0 rødt; 0–6,07 gult
A25: 2. STANDARD PROGNOSEFORMEL OG MÅNEDSRUTINE
A26: Trinn | B26: Formel / metode | C26: Forklaring | D26: Kontroll | F26: Månedlig aktivitet | G26: Dag 1–3 | H26: Dag 4–5 | I26: Dag 6–7 | J26: Dag 8 | K26: Dag 9 | L26: Dag 10 | M26: Leveranse | N26: Eier
A27: 1 | B27: Actual YTD = bokført M01–cutoff | C27: Låst regnskap hittil i året | D27: Avstem mot hovedbok | F27: Datainnhenting | G27: Lukk periode | H27: HR-uttrekk | I27: FS/prosjekt | M27: Datapakke | N27: Controller
A28: 2 | B28: ETC = prognose for resterende måneder | C28: Bygges fra driverne i tabellen over | D28: Ingen dobbeltelling | F28: Driveroppdatering | H28: Lønn/vakans | I28: BOA/EVU/SPE60 | J28: Drift/Capex | M28: Oppdatert ETC | N28: Eiere
A29: 3 | B29: EAC = Actual YTD + ETC | C29: Ny forventet helårsverdi | D29: Sammenlign med BUD2027 | F29: Analyse | J29: Avviksbro | K29: Scenario | M29: Analysepakke | N29: Controller
A30: 4 | B30: VAC = BUD2027 − EAC | C30: Positivt tall er gunstig for kostnader | D30: Vurder fortegn for inntekter | F30: Beslutning | K30: Ledermøte | M30: Beslutningslogg | N30: Ledelsen
A31: 5 | B31: VAC % = VAC / BUD2027 | C31: Normaliserer vesentligheten | D31: RAG: grønn ≥0; gul 0 til −5 %; rød <−5 % | F31: Publisering | L31: Lås LE | M31: Power BI / rapport | N31: Controller
A32: 6 | B32: Ny LE godkjennes og versjoneres | C32: Bevar forrige prognose for sporbarhet | D32: Dato, eier og kommentar obligatorisk
A35: SLIK BRUKES ARKET
A36: Ved hver månedsavslutning erstattes avsluttede måneder av bokførte tall. For resterende måneder oppdateres driverne — bemanning, kontrakter, prosjektfremdrift, studentproduksjon og investeringer. Summen av bokført hittil og gjenstående estimat blir ny Latest Estimate. Denne sammenlignes med BUD2027, og vesentlige avvik får eier, kommentar og tiltak.

Sheet Model Guide
A1: UiA HHU — Datamodell 2026–2027
A2: Importkontroll, nøkkeltall og oppsett for Power Pivot / Power BI
A4: Kontrollpunkt | B4: Verdi | D4: Modellstatus | E4: Omfang | F4: Merknad | H4: RAPPORTPAKKE
A5: FactBudget 2026 total | B5: =SUM(FactBudget[BudsjettBelop]) -> 130153825 | D5: Importert | E5: 16 kildetabeller | F5: Alle 1 448 datarader fra CSV-settet | H5: Ark | I5: Formål | J5: Hovedsignal
A6: FactGL 2026 LE total | B6: =SUM(FactGL[Belop_signert]) -> 129631567 | D6: Relasjoner dokumentert | E6: 22 relasjoner | F6: 11 kilde-relasjoner + 11 modellkompletteringer | H6: Executive Report | I6: 3-sekunders lederstatus | J6: 2026: +0,52 MNOK mot plan
A7: FactBudget 2027 inntekter | B7: {=SUM(SUMIFS(FactBudget_2027[BudsjettBelop],FactBudget_2027[Konto],{"3900","3670","3600","3630","3400","3420"}))} -> 2.8607e+08 | D7: DAX validert | E7: 36 mål | F7: Korrigert mot faktiske kolonnenavn | H7: Unit Analysis | I7: 300-sekunders detaljanalyse | J7: Rettsvitenskap +1,15 / Økonomi −0,71 MNOK
A8: FactBudget 2027 kostnader | B8: =SUM(FactBudget_2027[BudsjettBelop])-B7 -> 2.82e+08 | D8: Datamodellhandling | E8: Manuell sluttføring | F8: Legg Excel-tabellene i Data Model og opprett målene fra DAX Measures | H8: 2027 Plan Report | I8: Fremoverskuende beslutningsstøtte | J8: 4,07 MNOK resultat; 2,0 MNOK inntektsgap
A9: FactBudget 2027 netto resultat | B9: =B7-B8 -> 4069999.7
A12: Viktig datakvalitetsfunn | B12: CSV-verdi | C12: Dokumentert verdi | D12: Differanse | E12: Konsekvens | F12: Anbefaling
A13: BUD2027 inntekter | B13: 2.8607e+08 | C13: 288070000 | D13: -2000000.2 | E13: Netto blir 4,07 MNOK, ikke 6,07 MNOK | F13: Avklar manglende 2,0 MNOK inntektslinje før publisering
A16: Tabell | B16: Datarader | C16: Status
A17: DimAccountHierarchy | B17: 20 | C17: Importert
A18: DimDate | B18: 12 | C18: Importert
A19: DimDate_2027 | B19: 12 | C19: Importert
A20: DimForecastVersion | B20: 5 | C20: Importert
A21: DimOrganization | B21: 4 | C21: Importert
A22: FactAction | B22: 4 | C22: Importert
A23: FactAction_2027 | B23: 4 | C23: Importert
A24: FactBudget | B24: 432 | C24: Importert
A25: FactBudget_2027 | B25: 384 | C25: Importert
A26: FactEVM | B26: 12 | C26: Importert
A27: FactFTE | B27: 48 | C27: Importert
A28: FactFTE_2027 | B28: 48 | C28: Importert
... A32: Relationships | B32: 22 | C32: Importert

Sheet gr_data
A1: Grunnlagsdataene for Budsjett 2027, det tilhørende settet med DAX-målekoder og en grundig forklaring av prognosemodellene for Handelshøyskolen ved UiA (HHU) er nå klargjort og publisert som CSV-filer i Studio-panelet.
A4: 1. Genererte Grunnlagsdata for Budsjett 2027 (CSV-filer i Studio)
A5: De nye CSV-filene er strukturert for direkte import i Power BI Desktop (semi-kolon ; skilletegn, UTF-8 med BOM):
A7: FactBudget_2027.csv: Periodisert årsbudsjett for alle 12 måneder i 2027. Reflekterer HHUs samlede ramme på 288,07 MNOK i inntekter og 282,00 MNOK i kostnader, som gir et planlagt driftsüberskudd på +6,07 MNOK (baseline BAC +4,80 MNOK), fordelt på kontoplan DFØ R-102 og HHUs 4 budsjettansvarsområder.
A8: FactFTE_2027.csv: Bemannings- og årsverksplan for 2027. HHU disponerer 230 årsverk (155 UF og 75 TA fordelt på 252 ansatte), med en innlagt sentral 3,5 % vakansfaktor i UBW Planlegger for å ta høyde for naturlig rekrutteringstid (3–6 måneder).
A9: FactStudents_2027.csv: Utdannings- og studiepoengmodell for 2027. Dokumenterer 3 450 registrerte studenter og 3 153 SPE60 (hvor 33 SPE60 utgjør resultatvekst fra 2025-produksjonen utbetalt i Kategori 1 @ 54 550 kr/SPE60).
A10: FactAction_2027.csv: Omstillingstiltak T001_2027–T004_2027 (frys i administrativ rekruttering, faglig reallokering til Siviløkonom, lansering av EVU Master i HR, samt økt TDI research buy-out).
A11: DimDate_2027.csv, DimOrganization.csv, DimAccountHierarchy.csv, DimForecastVersion.csv: Dimensjonstabeller for 2027.
A15: 2. Komplett sett med DAX-målekoder for Budsjett 2027
A16: DAX-målekodene legges inn i Power BI i dedikerte Display Folders:
A18: // ===============================================================================
A19: // FOLDER 1: BUDSJETT 2027 BASELINE (_01 Budsjett 2027 BAC)
... A148: Tallstørrelse: I henhold til Rundskriv F-05-20 må ubrukte avsetninger utover 5 % av årets bevilgning være formelt bundet til Universitetsstyrets godkjente investeringsplaner (IT-fornyelse, laboratorier, AACSB-revisjon) for å forhindre statlig

Sheet bud2026
A1: 5
A2: Datatsettet, datamodell-diagrammet og relasjonstabellen er nå publisert i Studio-panelet som 11 CSV-filer og én HD-diagramfil (powerbi_datamodel_hhu_2026_diagram.png).
A5: 1. Fordeling på Budsjettansvarsområder (HHU 2026)
A6: I henhold til UiA sin organisasjonsstruktur og kontoplan3more_horiz er årsbudsjettet på 130 153 825 kr fordelt på HHUs fire primære budsjettansvarsområder (koststeder/enheter):
A7: Koststed / OrgKode | B7: Budsjettansvarsområde / Enhet | C7: Ansvarlig Leder | D7: Vedtatt Årsbudsjett 2026 (NOK) | E7: Andel % | F7: Sentrale Faglige og Operative Ansvarsområder
A8: K10000 | B8: HHU Fakultetsadministrasjon & Felles | C8: Fakultetsdirektør Kristian Jørgensen6 | D8: 14 000 000 kr | E8: 10,8 % | F8: AACSB re-akkreditering7, fellesinfrastruktur, IT-lisenser og overordnet fakultetsstyring6.
A9: K11000 | B9: Institutt for ledelse og innovasjon | C9: Instituttleder Ledelse4 | D9: 38 500 000 kr | E9: 29,6 % | F9: Master i org. og ledelse, bachelor i markedsføring, oppdragsutdanning (EVU)8.
A10: K12000 | B10: Institutt for rettsvitenskap | C10: Instituttleder Ole Dag Rike46 | D10: 29 250 000 kr | E10: 22,5 % | F10: Master og bachelor i rettsvitenskap (jus), lovpålagte emner for siviløkonomer9.
A11: K13000 | B11: Institutt for økonomi | C11: Instituttleder Økonomi4 | D11: 48 403 825 kr | E11: 37,2 % | F11: Siviløkonomstudiet (M-SIVØK), Bachelor i øk.ad, ph.d.-utdanning og NFR/EU-forskning3more_horiz.
A12: SUM HHU | B12: HANDELSHØYSKOLEN TOTAT | C12: Dekan Kristin Wallevik6 | D12: 130 153 825 kr | E12: 100,0 % | F12: Vedtatt totalramme for HHU i Universitetsstyret25.
A15: 2. Utfordringer i Datasetter knyttet til Budsjettansvarsområde (2026)
A16: Datamaterialet i FactGL.csv, FactFTE.csv og FactAction.csv er konstruert for å belyse fire klassiske styrings- og avviksutfordringer i matrisen mellom linjeansvar (instituttleder) og prosjektansvar (prosjektleder/studieprogramleder)11more_horiz:
A18: 1. Bemanningsavvik og vakansstyring (K13000 Inst. for økonomi):
A19: Utfordring: Instituttet har lav vakansrate fordi to nye førsteamanuenser startet tre måneder tidligere enn forutsatt i UBW-planleggeren.
A20: Effekt i data: Påløpte lønnskostnader YTD per 30. september viser et merforbruk på +3,5 % mot periodisert budsjett.
A21: 2. Kompenserende vakanshold (K12000 Inst. for rettsvitenskap):
A22: Utfordring: For å avlaste fakultetets samlede ramme holdes en professorhjemmel midlertidig ubesatt i Q2–Q3 (Tiltak T004_HHU).
A23: Effekt i data: Gir et akkumulert mindreforbruk på -800 000 kr i FactGL.csv og FactAction.csv.
A24: 3. SRS 9 Tapsavsetning på oppdragsutdanning (K11000 Inst. for ledelse):
A25: Utfordring: På oppdragsprosjektet EVU001 har timelærerforbruket overskredet kontraktsrammen. I henhold til SRS 9 kreves det umiddelbar inntektsføring etter fullføringsgrad og tapsavsetning14.
A26: Effekt i data: Postering på 350 000 kr på konto 7790 (Avsetning for forventet tap) i M09.
A27: 4. AACSB Akkrediteringskostnader vs. TDI Overhead (K10000 Admin):
... A246: 💡 Alt ligger klart i Studio-panelet ditt for videre analyse!

Sheet bud2027
A1: De nye strategiske midlene, regional støtte og studieplasstildelingene påvirker 2027-budsjettet ved Universitetet i Agder (UiA) gjennom tre hovedmekanismer: KDs resultatfinansiering med to års etterslep, indirekte kostnadsdekning (overhead) fra ekstern forskning (BOA), og rammebetingelsene for formålskapital og avsetninger (Note 15 og F-05-20).
A4: 1. Resultatbevilgning via KDs toårige etterslep
A6: Studiepoengproduksjon (SPE60): Tildelingen av nye studieplasser (blant annet 30 studieplasser til profesjonsstudiet i psykologi1, 10 studieplasser i IKT2 og arbeidsplassbasert barnehagelærerutdanning12) øker studentmassen og studiepoengproduksjonen i 2025 og 2026.
A7: Inntektseffekt i 2027: Under Kunnskapsdepartementets (KD) finansieringsmodell utbetales resultatbasert uttelling for avlagte studiepoeng med to års etterslep3more_horiz. Studiepoeng produsert av disse studentkullene i 2025 vil dermed gi direkte økt resultatbevilgning på statsbudsjettet for 2027 ut fra KDs tre finansieringskategorier (Kategori 1: 54 550 kr; Kategori 2: 81 800 kr; Kategori 3: 190 900 kr per 60 SPE)67.
A11: 2. Ekstern forskningsfinansiering og TDI-overhead (BOA)
A13: Regionale fond og stiftelser: Betydelige eksterne tilsagn – slik som Sør-fondets 30 mill. kr (hvorav 18 mill. kr går til nevrovitenskap)8, Sørlandets kompetansefonds 18 mill. kr over tre år8 og Aust-Agder utviklings- og kompetansefond8 – utvider UiAs eksternt finansierte prosjektportefølje (Bidrags- og oppdragsaktivitet / BOA).
A14: Periodisering etter SRS 10: I henhold til SRS 10 inntektsføres disse bidragsmidlene i 2027-budsjettet i eksakt takt med at prosjektkostnadene påløper (motsatt sammenstilling)9.
A15: Avlastning av basisrammen (TDI-modellen): Gjennom TDI-modellen (Totalkostnadsmodellen) dekker eksternt finansierte prosjekter sine egne direkte kostnader pluss et påslag for indirekte felleskostnader (overhead) til husleie, IT, bibliotek og administrasjon9more_horiz. Denne overhead-refusjonen overføres tilbake til fakultetene og fellestjenestene i 2027, noe som direkte avlaster universitetets faste basisbevilgning1011.
A19: 3. Engangssatsinger, investeringer og avsetningsreglementet (Note 15 & F-05-20)
A21: Strategiske engangsmidler: Løyvinger til KI og ny teknologi (over 18 mill. kr, hvorav 15 mill. kr til felles infrastruktur og 500 000 kr per fakultet)1213, fleksibel utdanning (6 mill. kr sentralt + 500 000 kr per fakultet)14 og Vitensenteret Kristiansand UiA (5 mill. kr til inventar/utstyr)14 utgjør tidsavgrensede eller engangsbaserte tildelinger.
A22: Binding i Note 15: Universitetets samlede avsetninger i Note 15 økte til 295,4 mill. kr per 31.12.20251516. Av dette er hele 257 mill. kr formelt avsatt til universitetsstyrets godkjente investeringsplan for 2026–2028 (som dekker campusutvikling, spesialarealer for psykologiutdanningen og Vitensenteret)15more_horiz.
A23: Kontroll mot F-05-20 (5 %-regelen): Ved å binde 13 % av bevilgningen til vedtatte investeringer, holdes UiAs frie avsetninger til andre formål på ca. 2 %1718. Dette sikrer at universitetet overholder KDs retningslinjer i Rundskriv F-05-20, samtidig som engangsmidler forhindres fra å skape udekket overbemanning eller faste driftsforpliktelser i 20271019.
... A43: Tabellen viser overgangen fra 2026-baseline12 til 2027-budsjett for HHU, spesifisert per inntektsstrøm, regnskapsprinsipp og kilde:
A44: Inntektskomponent | B44: 2026 Baseline (MNOK)1 | C44: Endring / Nye midler (NOK) | D44: 2027 Prognose (MNOK) | E44: Beregningsgrunnlag og Regnskapsregel
A45: Statlig grunnbevilgning (Basis) | B45: 246,80 | C45: +5 200 000 kr | D45: 252,00 | E45: Lønns- og prisjustering (~2,1 %) på den faste basisrammen34.
A46: KDs resultatbevilgning (SPE60) | B46: 0,00 (bakt i basis) | C46: +1 800 150 kr | D46: 1,80 | E46: 2-års etterslep: Marginalsats for Kategori 1 (54 550 kr/SPE60)56 for økt studiepoengproduksjon i 2025 (+33 SPE60).
A47: Strategiske engangsmidler (KI) | B47: 0,00 | C47: +500 000 kr | D47: 0,50 | E47: Styretildeling til hvert fakultet for implementering av KI og ny teknologi78.
A48: Strategiske midler (Fleksibilitet) | B48: 0,00 | C48: +500 000 kr | D48: 0,50 | E48: Styretildeling til hvert fakultet for fleksibilisering av studietilbud8.
A49: Øremerket støtte (AACSB) | B49: 0,2789 | C49: +0 kr (videreføres) | D49: 0,27 | E49: Særskilt tildeling fra Universitetsstyret til arbeidet med re-akkreditering89.
A50: Ekstern forskning (BOA - Bidrag) | B50: 18201 | C50: +1 800 000 kr | D50: 20,00 | E50: SRS 10 (Motsatt sammenstilling): Økt NFR/EU-frikjøp610. Inkluderer TDI-overhead910.
A51: Oppdrag & EVU (Studieavgifter) | B51: 11601 | C51: +1 400 000 kr | D51: 13,00 | E51: SRS 9 (Fullføringsgrad): Økning i markedsfinansierte videreutdanninger (f.eks. Master i HR og ledelse)1112.
A52: SAMLEDE INNTEKTER (HHU) | B52: 276,87 MNOK | C52: +11 200 150 kr | D52: 288,07 MNOK | E52: Samlet inntektsvekst på +4,0 % for HHU.
A55: 2. Regneeksempel for de tre viktigste inntektsdriverne
A56: A. KDs resultatbaserte uttelling (SPE60 i Kategori 1 med 2-års etterslep)
A57: HHUs studier (økonomi, ledelse, juss) er plassert i KDs Kategori 1, der insentivsatsen utgjør 54 550 kr per 60 avlagte studiepoeng (1 SPE60)56.
A58: Dersom HHU øker studentenes studiepoengproduksjon i 2025 med totalt 1 980 studiepoeng (tilsvarende +33 helårsstudenter / SPE60), utløser dette følgende inntektsvekst i 2027-budsjettet5:
A59: $$\text{Inntektseffekt i 2027} = 33 \text{ SPE60} \times 54\,550 \text{ kr/SPE60} = \mathbf{1\,800\,150 \text{ kr}} \quad (\mathbf{+1,80 \text{ MNOK}})$$
A60: Merk: Nettobudsjetteringsprinsippet gjør at eksisterende studievolum ligger fast i basis, så Kategori 1-satsen gjelder kun for marginale volumendringer56.
A63: B. Strategiske tildelinger fra Universitetsstyret
A64: I henhold til vedtak i Universitetsstyret tilføres HHU tre spesifikke strategiske tildelinger7more_horiz:
A66: 1. KI og ny teknologi: 500 000 kr direkte til fakultetets arbeid med KI i undervisning og forskning78.
A67: 2. Fleksible utdanningstilbud: 500 000 kr direkte til utvikling av nett- og samlingsbaserte tilbud8.
A68: 3. AACSB Re-akkreditering: 265 000 kr øremerket revisjon og internasjonalt kvalitetssikringsarbeid89.
A70: $$\text{Sum strategiske engangsmidler} = 500\,000 \text{ kr} + 500\,000 \text{ kr} + 265\,000 \text{ kr} = \mathbf{1\,265\,000 \text{ kr}} \quad (\mathbf{1,27 \text{ MNOK}})$$
... A86: Veksten drives av en kombinasjon av kr 1,8 MNOK i resultatvekst fra økt studiepoengproduksjon i Kategori 156, kr 1,27 MNOK i øremerkede strategiske midler til KI, fleksibilitet og AACSB7more_horiz, samt kr 3,2 MNOK i økt ekstern prosjektomsetning (BOA) gjennom frikjøp og studieavgifter1012.

Sheet org_data
A1: Use Case: Seniorrådgiver / Senior Controller ved Handelshøyskolen (HHU) – Universitetet i Agder
A4: 1. Stillingsprofil & Strategisk Kontekst
A5: Handelshøyskolen ved UiA (HHU) er internasjonalt AACSB-akkreditert, organisert i tre institutter (Ledelse og innovasjon, Rettsvitenskap, Økonomi) samt fakultetsadministrasjonen, med Hovedarbeidssted på Campus Kristiansand. Fakultetet håndterer om lag 3 450 registrerte studenter (3 120 SPE60-ekvivalenter), 230 årsverk (155 faglige UF-årsverk og 75 teknisk-administrative TA-årsverk) og en samlet helårsramme i 2026 på 276,6 MNOK i inntekter mot 274,4 MNOK i kostnader (netto avvik/overskudd: +2,2 MNOK).
A6: Stillingen som Seniorrådgiver / Senior Controller (stillingskode 1364) inngår i fakultetets økonomiteam i fakultetsadministrasjonen, rapporterer direkte til fakultetsdirektøren, og leverer strategisk beslutningsstøtte til dekan, instituttledere og sentral økonomiavdeling.
A8: +----------------------------------------------------------------------------------------------------+
A9: | ORGANISATORISK PLASSERING OG RAPPORTERINGSLINJE |
A10: +----------------------------------------------------------------------------------------------------+
A11: | Universitetsdirektør / Sentral Økonomiavdeling <---> Dekan & Fakultetsstyre ved HHU |
A12: | │ |
A13: | Fakultetsdirektør |
A14: | │ |
A15: | Seniorrådgiver / Senior Controller (Kode 1364) |
... A121: 5. Leveranser og Suksesskriterier for Seniorrådgiveren
A122: Område | B122: Mål og Kvalitetskrav | C122: Evaluering & Dokumentasjon
A123: Kvalitetssikring av Budsjett | B123: Konsolidere HHUs årsbudsjett i UBW Planlegger med korrekte sosiale kostnader, realistisk vakansfaktor og avstemt studiepoengprognose. | C123: Sjekkliste for systemfrys i Q4 fullført uten avvik.
A124: BOA- og TDI-oppfølging | B124: Sikre 100 % korrekt periodisering etter SRS 10 for NFR/EU-bidrag og full overhead-dekning på oppdragskontrakter. | C124: Null uidentifiserte avsetningstap ved tertialavslutning.
A125: Beslutningsstøtte til Dekan | B125: Utarbeide tertialvise månedsrapporter med "So What?"-analyse, RAG-status og 2–3 konkrete handlingsalternativer ved avvik. | C125: Presentert for dekan og instituttledere i dialogmøter.
A126: Power BI Cockpit | B126: Opprettholde rollestyrt tilgang (RLS) på fakultets- og instituttnivå, og sikre oppdaterte Power BI-dashbord i tråd med 3-30-300-regelen og Tufte-

Sheet meta_data
A1: complete, realistic CSV dataset, along with two technical architecture diagrams tailored specifically to the Handelshøyskolen ved UiA (HHU) financial and operational ecosystem for the 2026 budget year (with Actuals as of September 30, 2026 / M01–M09 and Q4 Forecast / M10–M12).
A2: All 11 CSV files and both high-resolution diagram images have been generated and published to your Studio panel.
A5: 1. Overview of Generated CSV Dataset (Published to Studio)
A6: The dataset is formatted with semi-colon (;) delimiters and UTF-8 BOM encoding for direct import into Power BI Desktop or Excel [1, 2].
A7: CSV Filename | B7: Table Type | C7: Key Contents & HHU-Specific Specifics
A8: FactGL.csv | B8: Fact Table | C8: Monthly general ledger entries [1]. Contains Actuals (M01–M09) and Forecast Q4 (M10–M12) [1]. Includes HHU transactions for AACSB accreditation audits (Konto 6700 / Project AACSB01), EVU001 contract loss provisions (Konto 7790 / SRS 9) [1], and NFR research buy-out (Konto 3400/5000 / SRS 10) [1].
A9: FactBudget.csv | B9: Fact Table | C9: Approved 2026 annual budget (BUD2026) periodized by month, department, and account line [1, 3].
A10: FactFTE.csv | B10: Fact Table | C10: Monthly staffing tracking [1]. For HHU: 155 UF FTEs (vitenskapelige) [2], 75 TA FTEs (teknisk-administrative) [2], 252 staff members, vacancy counts, and monthly salary expenses [1].
A11: FactStudents.csv | B11: Fact Table | C11: Student metrics and credit production [1]. Tracks HHU’s 3,450 registered students, 3,120 SPE60 (helårsstudenter), KD Category 1 rates (54,550 NOK/60 SPE), and student-to-faculty ratio (22.3 students/UF) [2, 4].
A12: FactEVM.csv | B12: Fact Table | C12: Earned Value parameters per month [1, 5]. BAC = 1,433.0 MNOK, EAC = 1,444.0 MNOK, ETC = 100.0 MNOK [2, 5], CPI = 0.95, SPI = 0.92, VAC = -11.0 MNOK [2, 5].
A13: FactAction.csv | B13: Fact Table | C13: Restructuring action tracker [1]. Includes HHU administrative vacancy freeze (T001), academic reallocation (T002), and EVU portfolio expansion (T003) [2, 6].
A14: DimOrganization.csv | B14: Dimension | C14: Hierarchical organization structure [1]. Level 1: UiA [2]; Level 2: HHU, TEK, HEL, SAM, HUM, ADM [2]; Level 3 (HHU): Institutt for ledelse og innovasjon (I001), Institutt for rettsvitenskap (I002), Institutt for økonomi (I003), HHU Fakultetsadministrasjon (I004).
A15: DimAccountHierarchy.csv | B15: Dimension | C15: DFØ R-102 standard chart of accounts hierarchy for state accrual accounting (SRS) [1, 7].
A16: DimDate.csv | B16: Dimension | C16: 2026 calendar dimension marking M01–M09 as Actual (ErActualYTD = TRUE) and M10–M12 as Forecast [1, 3].
A17: DimForecastVersion.csv | B17: Dimension | C17: Version metadata (BUD2026, ACTUAL_YTD_SEP2026, FC_Q4_2026, LE_2026) [1, 3].
A18: Relationships.csv | B18: Documentation | C18: Cardinality and cross-filtering rules ($1:*$ single direction) for setting up the Power BI semantic model [1].
A21: 2. Specific HHU Issues Represented in the Data
A23: 1. KD 2025 Category 1 Funding Bottleneck: HHU produces 3,120 SPE60 across its three institutes (Ledelse og innovasjon, Rettsvitenskap, Økonomi) [2]. Because business/law studies fall under KD Category 1 (54,550 NOK per 60 SPE) [4] and HHU operates at 22.3 students per UF FTE [2], marginal volume expansion does not cover clinical/seminar teaching costs [4].
A24: 2. AACSB Accreditation Costs: Account 6700 and Project AACSB01 capture 450,000 NOK in international review audit fees and consultant support in M03 and M09 to maintain HHU's international accreditation.
A25: 3. SRS 9 Contract Loss Provision (EVU001): Account 7790 records a 350,000 NOK loss provision in M09 for project EVU001 (custom corporate executive program) due to delivery overruns, complying with SRS 9 onerous contract rules [1].
A26: 4. SRS 10 NFR Research Buy-out (Frikjøp): Accounts 3400 and 5000 on project NFR001 reflect research buy-out where external grant revenue matches project expenses [1, 8].
A27: 5. Positive Net Surplus (+2.2 MNOK): HHU delivers total revenues of 276.6 MNOK against expenses of 274.4 MNOK, contributing +2.2 MNOK in positive operating margin to offset central deficits [2].
A31: 3. Data Workflow Diagram: Ingestion, ETL & Reporting
A32: The visual image data_workflow_ingestion_reporting.png is published in Studio. Below is the workflow breakdown:
A34: +---------------------------------------------------------------------------------------------------+
A35: | UiA DATA INGESTION & REPORTING PIPELINE WORKFLOW |
A36: +---------------------------------------------------------------------------------------------------+
A38: [ PHASE 1: SOURCE LAYER (Kildesystemer) ]
... A93: | [Studenter, SPE] | | EAC, CPI, SPI] | | Ansvarlig] |

Sheet bud_prosess
A1: Use Case: 2027 Budgeting & Financial Planning for Handelshøyskolen ved UiA (HHU)
A4: 1. Strategic Context & Organizational Framework
A5: Handelshøyskolen ved UiA (HHU) is an internationally AACSB-accredited business school at the University of Agder, organized into three academic departments (Institutt for ledelse og innovasjon, Institutt for rettsvitenskap, and Institutt for økonomi) plus the faculty administration on Campus Kristiansand.
A6: HHU operates with a 2026 baseline of 3,450 registered students (3,120 SPE60 credit-equivalents), 230 FTEs (155 academic/UF FTEs and 75 technical-administrative/TA FTEs), and a total annual operating budget of 276.6 MNOK in revenue against 274.4 MNOK in total expenses, yielding a net operating surplus of +2.2 MNOK.
A7: In accordance with the UiA Controller Framework and the position profile for Senior Controller / Seniorrådgiver (stillingskode 1364), the senior controller leads the 2027 budgeting cycle. The controller reports to the Faculty Director (Fakultetsdirektør) and works closely with the Dean (Dekan), Department Heads (Instituttledere), and the central University Financial Department (Sentral Økonomiavdeling) to prepare a realistic, driver-based 2027 budget (BUD2027) and 5-year long-term forecast (PROG2027–2031) in Unit4 UBW Planlegger.
A9: +----------------------------------------------------------------------------------------------------+
A10: | HHU 2027 BUDGET PLANNING & GOVERNANCE HIERARCHY |
A11: +----------------------------------------------------------------------------------------------------+
A12: | KD Award Letter (Tildelingsbrev Kap. 260) ──> UiA Board Allocation Frame |
A13: | │ |
A14: | Fakultetsdirektør |
A15: | │ |
... A76: Based on the 2026 baseline (276.6 MNOK Revenue / 274.4 MNOK Expenses), the table below presents the full 2027 budget reconciliation model (BUD2027) prepared by the Senior Controller:
A77: Budget Line Item | B77: Account Class / Source | C77: 2026 Baseline (MNOK) | D77: 2027 Adjustments / Drivers | E77: 2027 Budget (MNOK) | F77: Notes & Regulatory Justification
A78: KD State Allocation (Basis) | B78: Konto 3900 / Post 50 | C78: 246.8 | D78: +5.2 (Price/salary indexation ~2.1%) | E78: 252.0 | F78: Fixed basis protected by net budgeting.
A79: KD Performance (2025 SPE60 Lag) | B79: Konto 3900 / FS | C79: 0 | D79: +1.8 (+33 SPE60 @ Kat 1 54 550 kr) | E79: 1.8 | F79: 2-year lag payout from 2025 credit growth.
A80: Research Grants (NFR / EU) | B80: Konto 3400 / 3420 | C80: 18.2 | D80: +1.8 (Increased buy-out / TDI overhead) | E80: 20.0 | F80: SRS 10 revenue matching project expenses.
